package runtime.exceptions.catch2

import kotlin.test.*

@Test fun runTest() {
    try {
        println("Before")
        foo()
        println("After")
    } catch (e: Exception) {
        println("Caught Exception")
    } catch (e: Error) {
        println("Caught Error")
    } catch (e: Throwable) {
        println("Caught Throwable")
    }

    println("Done")
}

fun foo() {
    throw Error("Error happens")
    println("After in foo()")
}